<?xml version="1.0" encoding="utf-8" ?>
<!-- =================================================================================== -->
<!-- |    This document was autogenerated by xacro from /home/adarsh/catkin_ws/src/satellite_servicer/urdf/satellite_servicer_integration.urdf.xacro | -->
<!-- |    EDITING THIS FILE BY HAND IS NOT RECOMMENDED                                 | -->
<!-- =================================================================================== -->
<!-- Name your robot here -->
<robot name="satellite_servicer">
    <link name="dummy_link">
        <pose>0 0 0 0 0 0</pose>
    </link>
    <joint name="dummy_joint" type="fixed">
        <parent link="dummy_link" />
        <child link="satellite_link" />
    </joint>

    <link name="satellite_link">
        <inertial>
            <origin rpy="0 0 0" xyz="-0.0081358 -0.00019537 0.49571" />
            <mass value="10528" />
            <inertia ixx="14714" ixy="-8.8712" ixz="20.724" iyy="9803" iyz="-0.86237" izz="21153" />
        </inertial>

        <visual>
            <origin rpy="0 0 0" xyz="0 0 0" />
            <geometry>
                <mesh filename="package://satellite_servicer/meshes/satellite_link.STL" />
            </geometry>
            <material name="">
                <color rgba="0.96863 0.87843 0.6 1" />
            </material>
        </visual>
        <collision>
            <origin rpy="0 0 0" xyz="0 0 0" />
            <geometry>
                <mesh filename="package://satellite_servicer/meshes/satellite_link.STL" />
            </geometry>
        </collision>
    </link>

    <link name="base_link"> 
        <inertial>
            <origin rpy="0 0 0" xyz="1.7757E-08 2.2989E-08 0.35618" />
            <!-- <mass value="12.182" /> -->
            <mass value="4.0606" />
            <inertia ixx="0.38271" ixy="1.9144E-07" ixz="2.0659E-08" iyy="0.37762" iyz="-3.2358E-08" izz="0.060358" />
        </inertial>

        <visual>
            <origin rpy="0 0 0" xyz="0 0 0" />
            <geometry>
                <mesh filename="package://satellite_servicer/meshes/base_link.STL" />
            </geometry>
            <material name="">
                <color rgba="0.79216 0.81961 0.93333 1" />
            </material>
        </visual>
        <collision>
            <origin rpy="0 0 0" xyz="0 0 0" />
            <geometry>
                <mesh filename="package://satellite_servicer/meshes/base_link.STL" />
            </geometry>
        </collision>
    </link>
    <joint name="joint_1" type="revolute">
        <axis xyz="0 0 1" />
        <limit effort="1000000.0" lower="-1.5708" upper="1.5708" velocity="0.05" />
        <origin rpy="0 1.5708 0" xyz="1.375 0 1.5" />
        <parent link="satellite_link" />
        <child link="base_link" />
    </joint>
    <!-- <joint
    name="joint_1"
    type="continuous">
    <origin
      xyz="1.375 0 1.5"
      rpy="0 1.5708 0" />
    <parent
      link="satellite_link" />
    <child
      link="base_link" />
    <axis
      xyz="0 0 1" />
  </joint> -->

    <link name="shoulder_link">      
        <inertial>
            <origin rpy="0 0 0" xyz="-9.77E-15 0.17518 8.8295E-07" />
            <!-- <mass value="4.7164" /> -->
            <mass value="1.572" />
            <inertia ixx="0.048851" ixy="1.0262E-16" ixz="2.7072E-18" iyy="0.019289" iyz="-3.606E-16" izz="0.048746" />
        </inertial>

        <visual>
            <origin rpy="0 0 0" xyz="0 0 0" />
            <geometry>
                <mesh filename="package://satellite_servicer/meshes/shoulder_link.STL" />
            </geometry>
            <material name="">
                <color rgba="0.79216 0.81961 0.93333 1" />
            </material>
        </visual>
        <collision>
            <origin rpy="0 0 0" xyz="0 0 0" />
            <geometry>
                <mesh filename="package://satellite_servicer/meshes/shoulder_link.STL" />
            </geometry>
        </collision>
    </link>
    <joint name="joint_2" type="revolute">
        <axis xyz="0 0 1" />
        <limit effort="1000000.0" lower="-1.5708" upper="1.5708" velocity="0.05" />
        <origin rpy="1.5708 0 0" xyz="0 0 0.577" />
        <parent link="base_link" />
        <child link="shoulder_link" />
    </joint>
    <!-- <joint
    name="joint_2"
    type="continuous">
    <origin
      xyz="0 0 0.577"
      rpy="1.5708 0 0" />
    <parent
      link="base_link" />
    <child
      link="shoulder_link" />
    <axis
      xyz="0 0 1" />
    </joint> -->

    <link name="lower_limb_link">        
        <inertial>
            <origin rpy="0 0 0" xyz="-0.85056 -4.4409E-16 -4.4346E-06" />
            <!-- <mass value="32.363" /> -->
            <mass value="10.7876" />
            <inertia ixx="0.12288" ixy="1.7482E-17" ixz="-2.1305E-16" iyy="5.4983" iyz="2.5E-17" izz="5.4963" />
        </inertial>

        <visual>
            <origin rpy="0 0 0" xyz="0 0 0" />
            <geometry>
                <mesh filename="package://satellite_servicer/meshes/lower_limb_link.STL" />
            </geometry>
            <material name="">
                <color rgba="0.79608 0.82353 0.93725 1" />
            </material>
        </visual>
        <collision>
            <origin rpy="0 0 0" xyz="0 0 0" />
            <geometry>
                <mesh filename="package://satellite_servicer/meshes/lower_limb_link.STL" />
            </geometry>
        </collision>
    </link>
    <joint name="joint_3" type="revolute">
        <axis xyz="0 0 -1" />
        <limit effort="1000000.0" lower="-1.5708" upper="1.5708" velocity="0.05" />
        <origin rpy="1.5708 0 -1.5708" xyz="0 0.224 0" />
        <parent link="shoulder_link" />
        <child link="lower_limb_link" />
    </joint>
    <!-- <joint
    name="joint_3"
    type="continuous">
    <origin
      xyz="0 0.224 0"
      rpy="1.5708 0 -1.5708" />
    <parent
      link="shoulder_link" />
    <child
      link="lower_limb_link" />
    <axis
      xyz="0 0 -1" />
    </joint> -->

    <link name="upper_limb_link">
        <inertial>
            <origin rpy="0 0 0" xyz="-0.78599888276463 4.44089209850063E-16 -4.43460107302229E-06" />
            <!-- <mass value="29.7046419191429" /> -->
            <mass value="9.90154" />
            <inertia ixx="0.115110391817254" ixy="-4.53050554997357E-16" ixz="-3.95383995952211E-15" iyy="5.48795757159928" iyz="-2.21909970795336E-17" izz="5.4856363384719" />
        </inertial>

        <visual>
            <origin rpy="0 0 0" xyz="0 0 0" />
            <geometry>
                <mesh filename="package://satellite_servicer/meshes/upper_limb_link.STL" />
            </geometry>
            <material name="">
                <color rgba="0.796078431372549 0.823529411764706 0.937254901960784 1" />
            </material>
        </visual>
        <collision>
            <origin rpy="0 0 0" xyz="0 0 0" />
            <geometry>
                <mesh filename="package://satellite_servicer/meshes/upper_limb_link.STL" />
            </geometry>
        </collision>
    </link>
    <joint name="joint_4" type="revolute">
        <axis xyz="0 0 -1" />
        <limit effort="1000000.0" lower="-1.5708" upper="1.5708" velocity="0.05" />
        <origin rpy="0 0 0" xyz="-1.572 0 0" />
        <parent link="lower_limb_link" />
        <child link="upper_limb_link" />
    </joint>
    <!-- <joint
    name="joint_4"
    type="continuous">
    <origin
      xyz="-1.572 0 0"
      rpy="0 0 0" />
    <parent
      link="lower_limb_link" />
    <child
      link="upper_limb_link" />
    <axis
      xyz="0 0 -1" />
  </joint> -->

    <link name="wrist_link">
        <inertial>
            <origin rpy="0 0 0" xyz="-0.042406 -4.4409E-16 -0.00017855" />
            <!-- <mass value="4.5771" /> -->
            <mass value="1.5257" />
            <inertia ixx="0.018225" ixy="-1.696E-17" ixz="3.3795E-05" iyy="0.04206" iyz="-3.6634E-18" izz="0.042168" />
        </inertial>

        <visual>
            <origin rpy="0 0 0" xyz="0 0 0" />
            <geometry>
                <mesh filename="package://satellite_servicer/meshes/wrist_link.STL" />
            </geometry>
            <material name="">
                <color rgba="0.79216 0.81961 0.93333 1" />
            </material>
        </visual>
        <collision>
            <origin rpy="0 0 0" xyz="0 0 0" />
            <geometry>
                <mesh filename="package://satellite_servicer/meshes/wrist_link.STL" />
            </geometry>
        </collision>
    </link>
    <joint name="joint_5" type="revolute">
        <axis xyz="0 0 1" />
        <limit effort="1000000.0" lower="-1.5708" upper="1.5708" velocity="0.05" />
        <origin rpy="0 0 0" xyz="-1.572 0 0" />
        <parent link="upper_limb_link" />
        <child link="wrist_link" />
    </joint>
    <!-- <joint
    name="joint_5"
    type="continuous">
    <origin
      xyz="-1.572 0 0"
      rpy="0 0 0" />
    <parent
      link="upper_limb_link" />
    <child
      link="wrist_link" />
    <axis
      xyz="0 0 1" />
  </joint> -->

    <link name="end_effector_link"> 
        <inertial>
            <origin rpy="0 0 0" xyz="-0.22082 -1.7757E-08 8.5996E-07" />
            <!-- <mass value="12.182" /> -->
            <mass value="4.0606" />
            <inertia ixx="0.060358" ixy="-2.0659E-08" ixz="3.2358E-08" iyy="0.38271" iyz="1.9144E-07" izz="0.37762" />
        </inertial>

        <visual>
            <origin rpy="0 0 0" xyz="0 0 0" />
            <geometry>
                <mesh filename="package://satellite_servicer/meshes/end_effector_link.STL" />
            </geometry>
            <material name="">
                <color rgba="0.79216 0.81961 0.93333 1" />
            </material>
        </visual>
        <collision>
            <origin rpy="0 0 0" xyz="0 0 0" />
            <geometry>
                <mesh filename="package://satellite_servicer/meshes/end_effector_link.STL" />
            </geometry>
        </collision>
    </link>
    <joint name="joint_6" type="revolute">
        <axis xyz="0 0 1" />
        <limit effort="1000000.0" lower="-1.5708" upper="1.5708" velocity="0.05" />
        <origin rpy="-1.5708 0 0" xyz="-0.224 0 0" />
        <parent link="wrist_link" />
        <child link="end_effector_link" />
    </joint>
    <!-- <joint
    name="joint_6"
    type="continuous">
    <origin
      xyz="-0.224 0 0"
      rpy="-1.5708 0 0" />
    <parent
      link="wrist_link" />
    <child
      link="end_effector_link" />
    <axis
      xyz="0 0 1" />
    </joint> -->

    <link name="cutter_tool_link"> 
        <inertial>
            <origin rpy="0 0 0" xyz="-0.047661 -3.5401E-07 -3.3162E-08" />
            <!-- <mass value="0.57564" /> -->
            <mass value="0.019188" />
            <inertia ixx="0.00062759" ixy="7.4288E-09" ixz="2.8377E-08" iyy="0.0015691" iyz="-2.0787E-09" izz="0.0015691" />
        </inertial>

        <visual>
            <origin rpy="0 0 0" xyz="0 0 0" />
            <geometry>
                <mesh filename="package://satellite_servicer/meshes/cutter_tool_link.STL" />
            </geometry>
            <material name="">
                <color rgba="0.79216 0.81961 0.93333 1" />
            </material>
        </visual>
        <collision>
            <origin rpy="0 0 0" xyz="0 0 0" />
            <geometry>
                <mesh filename="package://satellite_servicer/meshes/cutter_tool_link.STL" />
            </geometry>
        </collision>
    </link>
    <joint name="joint_fixed" type="fixed">
        <origin rpy="0 0 0" xyz="-0.577 0 0" />
        <parent link="end_effector_link" />
        <child link="cutter_tool_link" />
        <axis xyz="0 0 0" />
    </joint>

    <link name="repair_sat_link">    
        <inertial>
            <origin rpy="0 0 0" xyz="1.775 -0.0051613 -1.0625" />
            <mass value="5237.8" />
            <inertia ixx="4615.7" ixy="-40.725" ixz="278" iyy="5805.4" iyz="-16.884" izz="6974" />
        </inertial>

        <visual>
            <origin rpy="0 0 0" xyz="0 0 0" />
            <geometry>
                <mesh filename="package://satellite_setup/meshes/repair_sat_link.STL" />
            </geometry>
            <material name="">
                <color rgba="0.96863 0.87843 0.6 1" />
            </material>
        </visual>
        <collision>
            <origin rpy="0 0 0" xyz="0 0 0" />
            <geometry>
                <mesh filename="package://satellite_setup/meshes/repair_sat_link.STL" />
            </geometry>
        </collision>
    </link>
    <joint name="joint_repair_fixed" type="fixed">
        <origin rpy="0 0 0" xyz="6.91333 -0.056 1.7" />
        <parent link="satellite_link" />
        <child link="repair_sat_link" />
        <axis xyz="0 0 0" />
    </joint>
    
    <transmission name="joint1_trans">
        <type>transmission_interface/SimpleTransmission</type>
        <joint name="joint_1">
            <hardwareInterface>hardware_interface/EffortJointInterface</hardwareInterface>
        </joint>
        <actuator name="joint1_motor">
            <hardwareInterface>hardware_interface/EffortJointInterface</hardwareInterface>
            <mechanicalReduction>1</mechanicalReduction>
        </actuator>
    </transmission>
    <transmission name="joint2_trans">
        <type>transmission_interface/SimpleTransmission</type>
        <joint name="joint_2">
            <hardwareInterface>hardware_interface/EffortJointInterface</hardwareInterface>
        </joint>
        <actuator name="joint2_motor">
            <hardwareInterface>hardware_interface/EffortJointInterface</hardwareInterface>
            <mechanicalReduction>1</mechanicalReduction>
        </actuator>
    </transmission>
    <transmission name="joint3_trans">
        <type>transmission_interface/SimpleTransmission</type>
        <joint name="joint_3">
            <hardwareInterface>hardware_interface/EffortJointInterface</hardwareInterface>
        </joint>
        <actuator name="joint3_motor">
            <hardwareInterface>hardware_interface/EffortJointInterface</hardwareInterface>
            <mechanicalReduction>1</mechanicalReduction>
        </actuator>
    </transmission>
    <transmission name="joint4_trans">
        <type>transmission_interface/SimpleTransmission</type>
        <joint name="joint_4">
            <hardwareInterface>hardware_interface/EffortJointInterface</hardwareInterface>
        </joint>
        <actuator name="joint4_motor">
            <hardwareInterface>hardware_interface/EffortJointInterface</hardwareInterface>
            <mechanicalReduction>1</mechanicalReduction>
        </actuator>
    </transmission>
    <transmission name="joint5_trans">
        <type>transmission_interface/SimpleTransmission</type>
        <joint name="joint_5">
            <hardwareInterface>hardware_interface/EffortJointInterface</hardwareInterface>
        </joint>
        <actuator name="joint5_motor">
            <hardwareInterface>hardware_interface/EffortJointInterface</hardwareInterface>
            <mechanicalReduction>1</mechanicalReduction>
        </actuator>
    </transmission>
    <transmission name="joint6_trans">
        <type>transmission_interface/SimpleTransmission</type>
        <joint name="joint_6">
            <hardwareInterface>hardware_interface/EffortJointInterface</hardwareInterface>
        </joint>
        <actuator name="joint6_motor">
            <hardwareInterface>hardware_interface/EffortJointInterface</hardwareInterface>
            <mechanicalReduction>1</mechanicalReduction>
        </actuator>
    </transmission>
    <!-- <transmission name="trans_joint_1">
        <type>transmission_interface/SimpleTransmission</type>
        <joint name="joint_1">
            <hardwareInterface>hardware_interface/EffortJointInterface</hardwareInterface>
        </joint>
        <actuator name="joint_1_motor">
            <hardwareInterface>hardware_interface/EffortJointInterface</hardwareInterface>
            <mechanicalReduction>1</mechanicalReduction>
        </actuator>
    </transmission>
    <transmission name="trans_joint_2">
        <type>transmission_interface/SimpleTransmission</type>
        <joint name="joint_2">
            <hardwareInterface>hardware_interface/EffortJointInterface</hardwareInterface>
        </joint>
        <actuator name="joint_2_motor">
            <hardwareInterface>hardware_interface/EffortJointInterface</hardwareInterface>
            <mechanicalReduction>1</mechanicalReduction>
        </actuator>
    </transmission>
    <transmission name="trans_joint_3">
        <type>transmission_interface/SimpleTransmission</type>
        <joint name="joint_3">
            <hardwareInterface>hardware_interface/EffortJointInterface</hardwareInterface>
        </joint>
        <actuator name="joint_3_motor">
            <hardwareInterface>hardware_interface/EffortJointInterface</hardwareInterface>
            <mechanicalReduction>1</mechanicalReduction>
        </actuator>
    </transmission>
    <transmission name="trans_joint_4">
        <type>transmission_interface/SimpleTransmission</type>
        <joint name="joint_4">
            <hardwareInterface>hardware_interface/EffortJointInterface</hardwareInterface>
        </joint>
        <actuator name="joint_4_motor">
            <hardwareInterface>hardware_interface/EffortJointInterface</hardwareInterface>
            <mechanicalReduction>1</mechanicalReduction>
        </actuator>
    </transmission>
    <transmission name="trans_joint_5">
        <type>transmission_interface/SimpleTransmission</type>
        <joint name="joint_5">
            <hardwareInterface>hardware_interface/EffortJointInterface</hardwareInterface>
        </joint>
        <actuator name="joint_5_motor">
            <hardwareInterface>hardware_interface/EffortJointInterface</hardwareInterface>
            <mechanicalReduction>1</mechanicalReduction>
        </actuator>
    </transmission>
    <transmission name="trans_joint_6">
        <type>transmission_interface/SimpleTransmission</type>
        <joint name="joint_6">
            <hardwareInterface>hardware_interface/EffortJointInterface</hardwareInterface>
        </joint>
        <actuator name="joint_6_motor">
            <hardwareInterface>hardware_interface/EffortJointInterface</hardwareInterface>
            <mechanicalReduction>1</mechanicalReduction>
        </actuator>
    </transmission> -->
    
    <!--  Gazebo plugin for control here is already added for you -->
    <gazebo>
        <plugin filename="libgazebo_ros_control.so" name="gazebo_ros_control">
            <robotNamespace>/satellite_servicer</robotNamespace>
            <robotSimType>gazebo_ros_control/DefaultRobotHWSim</robotSimType>
            <legacyModeNS>true</legacyModeNS>
        </plugin>
    </gazebo>
</robot>
